[2024-11-30T09:01:14.943+0000] {taskinstance.py:1956} INFO - Dependencies all met for dep_context=non-requeueable deps ti=<TaskInstance: weather_etl.fetch_weather manual__2024-11-30T09:01:06.923783+00:00 [queued]>
[2024-11-30T09:01:15.025+0000] {taskinstance.py:1956} INFO - Dependencies all met for dep_context=requeueable deps ti=<TaskInstance: weather_etl.fetch_weather manual__2024-11-30T09:01:06.923783+00:00 [queued]>
[2024-11-30T09:01:15.028+0000] {taskinstance.py:2170} INFO - Starting attempt 1 of 2
[2024-11-30T09:01:15.127+0000] {taskinstance.py:2191} INFO - Executing <Task(PythonOperator): fetch_weather> on 2024-11-30 09:01:06.923783+00:00
[2024-11-30T09:01:15.149+0000] {standard_task_runner.py:60} INFO - Started process 658 to run task
[2024-11-30T09:01:15.163+0000] {standard_task_runner.py:87} INFO - Running: ['***', 'tasks', 'run', 'weather_etl', 'fetch_weather', 'manual__2024-11-30T09:01:06.923783+00:00', '--job-id', '3', '--raw', '--subdir', 'DAGS_FOLDER/weather.py', '--cfg-path', '/tmp/tmppfw43tmk']
[2024-11-30T09:01:15.175+0000] {standard_task_runner.py:88} INFO - Job 3: Subtask fetch_weather
[2024-11-30T09:01:15.431+0000] {task_command.py:423} INFO - Running <TaskInstance: weather_etl.fetch_weather manual__2024-11-30T09:01:06.923783+00:00 [running]> on host 8d09c1752432
[2024-11-30T09:01:15.996+0000] {taskinstance.py:2480} INFO - Exporting env vars: AIRFLOW_CTX_DAG_OWNER='***' AIRFLOW_CTX_DAG_ID='weather_etl' AIRFLOW_CTX_TASK_ID='fetch_weather' AIRFLOW_CTX_EXECUTION_DATE='2024-11-30T09:01:06.923783+00:00' AIRFLOW_CTX_TRY_NUMBER='1' AIRFLOW_CTX_DAG_RUN_ID='manual__2024-11-30T09:01:06.923783+00:00'
[2024-11-30T09:01:17.129+0000] {taskinstance.py:2698} ERROR - Task failed with exception
Traceback (most recent call last):
  File "/home/airflow/.local/lib/python3.8/site-packages/airflow/models/taskinstance.py", line 433, in _execute_task
    result = execute_callable(context=context, **execute_callable_kwargs)
  File "/home/airflow/.local/lib/python3.8/site-packages/airflow/operators/python.py", line 199, in execute
    return_value = self.execute_callable()
  File "/home/airflow/.local/lib/python3.8/site-packages/airflow/operators/python.py", line 216, in execute_callable
    return self.python_callable(*self.op_args, **self.op_kwargs)
  File "/opt/airflow/dags/weather.py", line 18, in fetch_weather_data
    response.raise_for_status()
  File "/home/airflow/.local/lib/python3.8/site-packages/requests/models.py", line 1021, in raise_for_status
    raise HTTPError(http_error_msg, response=self)
requests.exceptions.HTTPError: 403 Client Error: Forbidden for url: https://api.weatherapi.com/v1/current.json?key=0de7c0ddab855314884f3f9b7f54e629&q=London
[2024-11-30T09:01:17.231+0000] {taskinstance.py:1138} INFO - Marking task as UP_FOR_RETRY. dag_id=weather_etl, task_id=fetch_weather, execution_date=20241130T090106, start_date=20241130T090114, end_date=20241130T090117
[2024-11-30T09:01:17.286+0000] {standard_task_runner.py:107} ERROR - Failed to execute job 3 for task fetch_weather (403 Client Error: Forbidden for url: https://api.weatherapi.com/v1/current.json?key=0de7c0ddab855314884f3f9b7f54e629&q=London; 658)
[2024-11-30T09:01:17.324+0000] {local_task_job_runner.py:234} INFO - Task exited with return code 1
[2024-11-30T09:01:17.440+0000] {taskinstance.py:3280} INFO - 0 downstream tasks scheduled from follow-on schedule check
